Workbook

Sheet Clasificacion EDGE
B5: WBS EDGE
B7: Instrucciones
B8: 1. Realiza un save as de este documento en la carpeta del proyecto correspondiente.
B9: 2. Ajusta tu WBS considerando las actividades que aplican a tu proyecto.
B10: 3. Cuadra las horas considerando el presupuesto de horas otorgado por tu Gerente de Operaciones.
B11: 4. Dírígete a la hoja de "WBS outputs" y descárgala
B12: 5. Dirígete a la hoja de "Etapas_outputs" y descárgala.
B13: 6. Importa en SmartSuite los documentos descargados siguiendo los pasos de la presentación "Proceso de recepción de proyecto_PM".
B18: 1 día equivale a ,2
B19: 1 semana equivale a 1

Sheet Validacion WBS
A1: Fecha estimada de inicio | E1: 45839 | I1: Tiempos Equipo | L1: Tiempos pendientes Equipo | P1: Actividades
A2: Bloque | B2: Actividad | C2: Horas estimadas (mediano) | D2: Duracion (semanas) | E2: Fecha inicio | F2: Fecha fin | G2: Descripción de actividades | H2: CJ | I2: CS | J2: PM | K2: Auditor | L2: HPen CJ | M2: HPen CS | N2: HPen PM | O2: HPen Auditor | P2: Críticas
A3: 0. Carga en Smart Suite | B3: 0.1 Gestión de proyecto | C3: =SUM(H3:K3) -> 6 | D3: 0.2 | E3: =_xlfn.WORKDAY.INTL(E1, 1, 1,'PONER VACACIONES'!$B$4:$B$24) -> #REF! | F3: =_xlfn.WORKDAY.INTL(E3, D3*5, 1,'PONER VACACIONES'!$B$4:$B$24) -> #REF! | G3: Gestionar y programar el WBS del proyecto en Smart Suite. | H3: 0 | I3: 0 | J3: 6 | K3: 0 | L3: =H3 -> 0 | M3: =I3 -> 0 | N3: =J3 -> 6 | O3: =K3 -> 0 | P3: FALSE
A4: 1. Seguimiento | B4: 1.1 Reuniones con el cliente | C4: =SUM(H4:K4) -> 12 | D4: 120 | E4: =_xlfn.WORKDAY.INTL(E1, 1, 1,'PONER VACACIONES'!$B$4:$B$24) -> #REF! | F4: =_xlfn.WORKDAY.INTL(E4, D4*5, 1,'PONER VACACIONES'!$B$4:$B$24) -> #REF! | G4: Atender reuniones con el cliente | H4: 0 | I4: 4 | J4: 8 | K4: 0 | L4: =H4 -> 0 | M4: =I4 -> 4 | N4: =J4 -> 8 | O4: =K4 -> 0 | P4: FALSE
A5: 1. Seguimiento | B5: 1.2 Kick-off | C5: =SUM(H5:K5) -> 2 | D5: 0.2 | E5: =_xlfn.WORKDAY.INTL(E1+1, 1, 1,'PONER VACACIONES'!$B$4:$B$24) -> #REF! | F5: =_xlfn.WORKDAY.INTL(E5, D5*5, 1,'PONER VACACIONES'!$B$4:$B$24) -> #REF! | G5: Exponer ante el cliente el comportamiento del proyecto en EDGE. Explicar las estrategias a seguir y las metas de la certificación. | H5: 0 | I5: 1 | J5: 1 | K5: 0 | L5: =H5 -> 0 | M5: =I5 -> 1 | N5: =J5 -> 1 | O5: =K5 -> 0 | P5: FALSE
A6: 2. EDGE Expert: Diseño Integrado | B6: 2.1 Evaluación inicial en EDGE App | C6: =SUM(H6:K6) -> 6 | D6: 0.2 | E6: =_xlfn.WORKDAY.INTL(F5, 1, 1,'PONER VACACIONES'!$B$4:$B$24) -> #REF! | F6: =_xlfn.WORKDAY.INTL(E6, D6*5, 1,'PONER VACACIONES'!$B$4:$B$24) -> #REF! | G6: Revisar la información compartida y evaluar el proyecto en la EDGE App. | H6: 2 | I6: 3 | J6: 1 | K6: 0 | L6: =H6 -> 2 | M6: =I6 -> 3 | N6: =J6 -> 1 | O6: =K6 -> 0 | P6: FALSE
A7: 2. EDGE Expert: Diseño Integrado | B7: 2.2 Revisión de diseño arquitectónico y de ingeniería | C7: =SUM(H7:K7) -> 8 | D7: 1 | E7: =_xlfn.WORKDAY.INTL(F5, 1, 1,'PONER VACACIONES'!$B$4:$B$24) -> #REF! | F7: =_xlfn.WORKDAY.INTL(E7, D7*5, 1,'PONER VACACIONES'!$B$4:$B$24) -> #REF! | G7: Revisar los avances de las ingenierías del proyecto detéctando áreas de oportunidad y mejora para cumplir con los objetivos de EDGE. | H7: 2 | I7: 5 | J7: 1 | K7: 0 | L7: =H7 -> 2 | M7: =I7 -> 5 | N7: =J7 -> 1 | O7: =K7 -> 0 | P7: FALSE
A8: 3. EDGE Expert: Seguimiento | B8: 3.1. Reuniones de seguimiento con cliente | C8: =SUM(H8:K8) -> 18 | D8: 12 | E8: =_xlfn.WORKDAY.INTL(F5, 1, 1,'PONER VACACIONES'!$B$4:$B$24) -> #REF! | F8: =_xlfn.WORKDAY.INTL(E8, D8*5, 1,'PONER VACACIONES'!$B$4:$B$24) -> #REF! | G8: Programar y llevar reuniones con el cliente y los equipos de trabajo para explicar si se está cumpliendo con las estrategias persegidas. | H8: 0 | I8: 6 | J8: 12 | K8: 0 | L8: =H8 -> 0 | M8: =I8 -> 6 | N8: =J8 -> 12 | O8: =K8 -> 0 | P8: FALSE
A9: 3. EDGE Expert: Seguimiento | B9: 3.2 Coordinación con equipo de diseño y ajustes | C9: =SUM(H9:K9) -> 12 | D9: 4 | E9: =_xlfn.WORKDAY.INTL(E5, 1, 1,'PONER VACACIONES'!$B$4:$B$24) -> #REF! | F9: =_xlfn.WORKDAY.INTL(E9, D9*5, 1,'PONER VACACIONES'!$B$4:$B$24) -> #REF! | G9: Capacitaciones para el equipo de diseño, revisión de planos y sugerencias. | H9: 0 | I9: 4 | J9: 8 | K9: 0 | L9: =H9 -> 0 | M9: =I9 -> 4 | N9: =J9 -> 8 | O9: =K9 -> 0 | P9: FALSE
A10: 4. EDGE Expert: Documentación Diseño | B10: 4.1 Alta del proyecto en EDGE APP y verificación de versión | C10: =SUM(H10:K10) -> 3 | D10: 0.2 | E10: =_xlfn.WORKDAY.INTL(F9, 1, 1,'PONER VACACIONES'!$B$4:$B$24) -> #REF! | F10: =_xlfn.WORKDAY.INTL(E10, D10*5, 1,'PONER VACACIONES'!$B$4:$B$24) -> #REF! | G10: Realizar el registro del proyecto, solicitar al cliente los datos de registro a través de un RFI. | H10: 0 | I10: 2 | J10: 1 | K10: 0 | L10: =H10 -> 0 | M10: =I10 -> 2 | N10: =J10 -> 1 | O10: =K10 -> 0 | P10: FALSE
A11: 4. EDGE Expert: Documentación Diseño | B11: 4.2 Configuración de parámetros base y tipologías | C11: =SUM(H11:K11) -> 3 | D11: 0.2 | E11: =_xlfn.WORKDAY.INTL(E6, 1, 1,'PONER VACACIONES'!$B$4:$B$24) -> #REF! | F11: =_xlfn.WORKDAY.INTL(E11, D11*5, 1,'PONER VACACIONES'!$B$4:$B$24) -> #REF! | G11: Definir y generar tipologías del proyecto | H11: 2 | I11: 1 | J11: 0 | K11: 0 | L11: =H11 -> 2 | M11: =I11 -> 1 | N11: =J11 -> 0 | O11: =K11 -> 0 | P11: FALSE
A12: 4. EDGE Expert: Documentación Diseño | B12: 4.3. Revisión de planos y fichas técnicas | C12: =SUM(H12:K12) -> 6 | D12: 120 | E12: =_xlfn.WORKDAY.INTL(E6, 1, 1,'PONER VACACIONES'!$B$4:$B$24) -> #REF! | F12: =_xlfn.WORKDAY.INTL(E12, D12*5, 1,'PONER VACACIONES'!$B$4:$B$24) -> #REF! | G12: Revisión de planos as-built y fichas técnicas, generación de issues log y recomendaciones. | H12: 2 | I12: 3 | J12: 1 | K12: 0 | L12: =H12 -> 2 | M12: =I12 -> 3 | N12: =J12 -> 1 | O12: =K12 -> 0 | P12: FALSE
A13: 4. EDGE Expert: Documentación Diseño | B13: 4.4 Design | C13: =SUM(H13:K13) -> 4.5 | D13: 0.2 | E13: =_xlfn.WORKDAY.INTL(E9, 1, 1,'PONER VACACIONES'!$B$4:$B$24) -> #REF! | F13: =_xlfn.WORKDAY.INTL(E13, D13*5, 1,'PONER VACACIONES'!$B$4:$B$24) -> #REF! | G13: Realizar el llenado de la pestaña de diseño en EDGE App. Subir los documentos correspondientes. | H13: 2.5 | I13: 1.5 | J13: 0.5 | K13: 0 | L13: =H13 -> 2.5 | M13: =I13 -> 1.5 | N13: =J13 -> 0.5 | O13: =K13 -> 0 | P13: FALSE
A14: 4. EDGE Expert: Documentación Diseño | B14: 4.5 EEM01* Window-to-Wall Ratio | C14: =SUM(H14:K14) -> 5 | D14: 0.2 | E14: =_xlfn.WORKDAY.INTL(E9, 1, 1,'PONER VACACIONES'!$B$4:$B$24) -> #REF! | F14: =_xlfn.WORKDAY.INTL(E14, D14*5, 1,'PONER VACACIONES'!$B$4:$B$24) -> #REF! | G14: Revisar los alzados del proyecto para calcular la proporción de ventana-muro, llenar calculadora en EDGE App y subir documentación correspondiente. | H14: 2.5 | I14: 2 | J14: 0.5 | K14: 0 | L14: =H14 -> 2.5 | M14: =I14 -> 2 | N14: =J14 -> 0.5 | O14: =K14 -> 0 | P14: TRUE
A15: 4. EDGE Expert: Documentación Diseño | B15: 4.6 EEM02 Reflective Roof: Solar Reflectance Index | C15: =SUM(H15:K15) -> 2.5 | D15: 0.2 | E15: =_xlfn.WORKDAY.INTL(F14, 1, 1,'PONER VACACIONES'!$B$4:$B$24) -> #REF! | F15: =_xlfn.WORKDAY.INTL(E15, D15*5, 1,'PONER VACACIONES'!$B$4:$B$24) -> #REF! | G15: Revisar el plano de acabados de techo, investigar la ficha técnica del material propuesto, llenar la calculadora de la EDGE App y subir documentación correspondiente. | H15: 1 | I15: 1 | J15: 0.5 | K15: 0 | L15: =H15 -> 1 | M15: =I15 -> 1 | N15: =J15 -> 0.5 | O15: =K15 -> 0 | P15: FALSE
A16: 4. EDGE Expert: Documentación Diseño | B16: 4.7 EEM03 Reflective Exterior Walls | C16: =SUM(H16:K16) -> 2.5 | D16: 0.2 | E16: =_xlfn.WORKDAY.INTL(F14, 1, 1,'PONER VACACIONES'!$B$4:$B$24) -> #REF! | F16: =_xlfn.WORKDAY.INTL(E16, D16*5, 1,'PONER VACACIONES'!$B$4:$B$24) -> #REF! | G16: Revisar los planos de acabados de muros exteriores, investigar la ficha técnica del material propuesto, llenar la calculadora de la EDGE App y subir documentación correspondiente. | H16: 1 | I16: 1 | J16: 0.5 | K16: 0 | L16: =H16 -> 1 | M16: =I16 -> 1 | N16: =J16 -> 0.5 | O16: =K16 -> 0 | P16: FALSE
A17: 4. EDGE Expert: Documentación Diseño | B17: 4.8 EEM04 External Shading Devices | C17: =SUM(H17:K17) -> 5.5 | D17: 0.2 | E17: =_xlfn.WORKDAY.INTL(F14, 1, 1,'PONER VACACIONES'!$B$4:$B$24) -> #REF! | F17: =_xlfn.WORKDAY.INTL(E17, D17*5, 1,'PONER VACACIONES'!$B$4:$B$24) -> #REF! | G17: Revisar planos de fachadas, resaltando los louvers o protecciones solares, generar detalles de ventanería con la profundidad de las protecciones, llenar calculadora y cálculos en la EDGE App y subir documentación correspondiente. | H17: 3 | I17: 2 | J17: 0.5 | K17: 0 | L17: =H17 -> 3 | M17: =I17 -> 2 | N17: =J17 -> 0.5 | O17: =K17 -> 0 | P17: FALSE
A18: 4. EDGE Expert: Documentación Diseño | B18: 4.9 EEM05* Insulation of Roof | C18: =SUM(H18:K18) -> 1.5 | D18: 0.2 | E18: =_xlfn.WORKDAY.INTL(F17, 1, 1,'PONER VACACIONES'!$B$4:$B$24) -> #REF! | F18: =_xlfn.WORKDAY.INTL(E18, D18*5, 1,'PONER VACACIONES'!$B$4:$B$24) -> #REF! | G18: Revisar el plano de especificaciones de sistema constructivo de techo, investigar la ficha técnica del material propuesto, llenar la calculadora de la EDGE App y subir documentación correspondiente. | H18: 1 | I18: 0.5 | J18: 0 | K18: 0 | L18: =H18 -> 1 | M18: =I18 -> 0.5 | N18: =J18 -> 0 | O18: =K18 -> 0 | P18: TRUE
A19: 4. EDGE Expert: Documentación Diseño | B19: 4.10 EEM06* Insulation of Ground/Raised Floor Slab | C19: =SUM(H19:K19) -> 1.5 | D19: 0.2 | E19: =_xlfn.WORKDAY.INTL(F18, 1, 1,'PONER VACACIONES'!$B$4:$B$24) -> #REF! | F19: =_xlfn.WORKDAY.INTL(E19, D19*5, 1,'PONER VACACIONES'!$B$4:$B$24) -> #REF! | G19: Revisar el plano de especificaciones de sistema constructivo de entrepisos, investigar la ficha técnica del material propuesto, llenar la calculadora de la EDGE App y subir documentación correspondiente. | H19: 1 | I19: 0.5 | J19: 0 | K19: 0 | L19: =H19 -> 1 | M19: =I19 -> 0.5 | N19: =J19 -> 0 | O19: =K19 -> 0 | P19: FALSE
A20: 4. EDGE Expert: Documentación Diseño | B20: 4.11 EEM07 Green Roof | C20: =SUM(H20:K20) -> 2.5 | D20: 0.2 | E20: =_xlfn.WORKDAY.INTL(F19, 1, 1,'PONER VACACIONES'!$B$4:$B$24) -> #REF! | F20: =_xlfn.WORKDAY.INTL(E20, D20*5, 1,'PONER VACACIONES'!$B$4:$B$24) -> #REF! | G20: Revisar plano de azotea con especificaciones del techo verde, generar una sección de techo considerando las capas de los materiales, calcular Leaf area Index considerando las copas de los árboles considerados. Llenar apartados en la EDGE App y subir documentación correspondiente. | H20: 1 | I20: 1 | J20: 0.5 | K20: 0 | L20: =H20 -> 1 | M20: =I20 -> 1 | N20: =J20 -> 0.5 | O20: =K20 -> 0 | P20: FALSE
A21: 4. EDGE Expert: Documentación Diseño | B21: 4.12 EEM08* Insulation of Exterior Walls | C21: =SUM(H21:K21) -> 1.5 | D21: 0.2 | E21: =_xlfn.WORKDAY.INTL(F20, 1, 1,'PONER VACACIONES'!$B$4:$B$24) -> #REF! | F21: =_xlfn.WORKDAY.INTL(E21, D21*5, 1,'PONER VACACIONES'!$B$4:$B$24) -> #REF! | G21: Revisar el plano de especificaciones de sistema constructivo de muros, investigar la ficha técnica del material propuesto, llenar la calculadora de la EDGE App y subir documentación correspondiente. | H21: 1 | I21: 0.5 | J21: 0 | K21: 0 | L21: =H21 -> 1 | M21: =I21 -> 0.5 | N21: =J21 -> 0 | O21: =K21 -> 0 | P21: FALSE
A22: 4. EDGE Expert: Documentación Diseño | B22: 4.13 EEM09* Efficiency of Glass | C22: =SUM(H22:K22) -> 2.5 | D22: 0.2 | E22: =_xlfn.WORKDAY.INTL(F21, 1, 1,'PONER VACACIONES'!$B$4:$B$24) -> #REF! | F22: =_xlfn.WORKDAY.INTL(E22, D22*5, 1,'PONER VACACIONES'!$B$4:$B$24) -> #REF! | G22: Revisar plano de ventanería para determinar la especificación del cristal, investigar ficha técnica, llenar información en EDGE App y subir documentación correspondiente. | H22: 2 | I22: 0.5 | J22: 0 | K22: 0 | L22: =H22 -> 2 | M22: =I22 -> 0.5 | N22: =J22 -> 0 | O22: =K22 -> 0 | P22: FALSE
A23: 4. EDGE Expert: Documentación Diseño | B23: 4.14 EEM10 Air Infiltration of Envelope | C23: =SUM(H23:K23) -> 6 | D23: 0.2 | E23: =_xlfn.WORKDAY.INTL(F22+30, 1, 1,'PONER VACACIONES'!$B$4:$B$24) -> #REF! | F23: =_xlfn.WORKDAY.INTL(E23, D23*5, 1,'PONER VACACIONES'!$B$4:$B$24) -> #REF! | G23: Gestionar blower door test para confirmar hermeticidad, documentar planos y detalles arquitectónicos de los componentes a cumplir con la hermeticidad del edificio. Llenar calculadora y apartados en la EDGE App, y subir documentación correspondiente. | H23: 3 | I23: 2 | J23: 1 | K23: 0 | L23: =H23 -> 3 | M23: =I23 -> 2 | N23: =J23 -> 1 | O23: =K23 -> 0 | P23: FALSE
A24: 4. EDGE Expert: Documentación Diseño | B24: 4.15 EEM11 Natural Ventilation | C24: =SUM(H24:K24) -> 8 | D24: 0.4 | E24: =_xlfn.WORKDAY.INTL(F22, 1, 1,'PONER VACACIONES'!$B$4:$B$24) -> #REF! | F24: =_xlfn.WORKDAY.INTL(E24, D24*5, 1,'PONER VACACIONES'!$B$4:$B$24) -> #REF! | G24: Revisar planos arquitectónicos para verificar proporción de ventanas operables y condiciones de ventilación cruzada. Elaborar diagramas de flujo de aire y cálculo de porcentaje de área operable. Llenar EDGE App y subir planos y diagramas de soporte. | H24: 5 | I24: 2 | J24: 1 | K24: 0 | L24: =H24 -> 5 | M24: =I24 -> 2 | N24: =J24 -> 1 | O24: =K24 -> 0 | P24: FALSE
A25: 4. EDGE Expert: Documentación Diseño | B25: 4.16 EEM12 Ceiling Fans | C25: =SUM(H25:K25) -> 4 | D25: 0.2 | E25: =_xlfn.WORKDAY.INTL(F24, 1, 1,'PONER VACACIONES'!$B$4:$B$24) -> #REF! | F25: =_xlfn.WORKDAY.INTL(E25, D25*5, 1,'PONER VACACIONES'!$B$4:$B$24) -> #REF! | G25: Revisar planos arquitectónicos y eléctricos para confirmar número y ubicación de ventiladores de techo. Validar fichas técnicas y elaborar cuadro resumen de unidades por tipo de espacio. Llenar EDGE App y subir documentación correspondiente. | H25: 1 | I25: 2.5 | J25: 0.5 | K25: 0 | L25: =H25 -> 1 | M25: =I25 -> 2.5 | N25: =J25 -> 0.5 | O25: =K25 -> 0 | P25: FALSE
A26: 4. EDGE Expert: Documentación Diseño | B26: 4.17 EEM13* Cooling System Efficiency | C26: =SUM(H26:K26) -> 5 | D26: 0.2 | E26: =_xlfn.WORKDAY.INTL(F24, 1, 1,'PONER VACACIONES'!$B$4:$B$24) -> #REF! | F26: =_xlfn.WORKDAY.INTL(E26, D26*5, 1,'PONER VACACIONES'!$B$4:$B$24) -> #REF! | G26: Revisar planos de sistema HVAC, revisar eficiencia en fichas técnicas, llenar la calculadora en la EDGE App y subir la documentación correpondiente. | H26: 2 | I26: 2 | J26: 1 | K26: 0 | L26: =H26 -> 2 | M26: =I26 -> 2 | N26: =J26 -> 1 | O26: =K26 -> 0 | P26: FALSE
A27: 4. EDGE Expert: Documentación Diseño | B27: 4.18 EEM14 Variable Speed Drives | C27: =SUM(H27:K27) -> 3.5 | D27: 0.2 | E27: =_xlfn.WORKDAY.INTL(F26, 1, 1,'PONER VACACIONES'!$B$4:$B$24) -> #REF! | F27: =_xlfn.WORKDAY.INTL(E27, D27*5, 1,'PONER VACACIONES'!$B$4:$B$24) -> #REF! | G27: Revisar planos de sistemas HVAC para confirmar instalación de variadores de frecuencia en motores. Validar fichas técnicas de los equipos y elaborar cuadro resumen de potencias controladas. Llenar EDGE App y subir documentación correspondiente. | H27: 2 | I27: 1 | J27: 0.5 | K27: 0 | L27: =H27 -> 2 | M27: =I27 -> 1 | N27: =J27 -> 0.5 | O27: =K27 -> 0 | P27: FALSE
A28: 4. EDGE Expert: Documentación Diseño | B28: 4.19 EEM15 Fresh Air Pre-Conditioning System | C28: =SUM(H28:K28) -> 6 | D28: 0.2 | E28: =_xlfn.WORKDAY.INTL(F27, 1, 1,'PONER VACACIONES'!$B$4:$B$24) -> #REF! | F28: =_xlfn.WORKDAY.INTL(E28, D28*5, 1,'PONER VACACIONES'!$B$4:$B$24) -> #REF! | G28: Revisar planos de sistemas de aire acondicionado para confirmar integración de pre-acondicionamiento de aire exterior. Validar fichas técnicas de equipos y elaborar cuadro resumen de capacidad. Llenar EDGE App y subir documentación correspondiente. | H28: 3 | I28: 2 | J28: 1 | K28: 0 | L28: =H28 -> 3 | M28: =I28 -> 2 | N28: =J28 -> 1 | O28: =K28 -> 0 | P28: FALSE
A29: 4. EDGE Expert: Documentación Diseño | B29: 4.20 EEM16* Space Heating System Efficiency | C29: =SUM(H29:K29) -> 6 | D29: 0.2 | E29: =_xlfn.WORKDAY.INTL(F28, 1, 1,'PONER VACACIONES'!$B$4:$B$24) -> #REF! | F29: =_xlfn.WORKDAY.INTL(E29, D29*5, 1,'PONER VACACIONES'!$B$4:$B$24) -> #REF! | G29: Revisar planos y fichas técnicas de equipos de calefacción para confirmar rendimiento energético. Elaborar cuadro de eficiencias y registrar en EDGE App con documentación de soporte. | H29: 3 | I29: 2 | J29: 1 | K29: 0 | L29: =H29 -> 3 | M29: =I29 -> 2 | N29: =J29 -> 1 | O29: =K29 -> 0 | P29: TRUE
A30: 4. EDGE Expert: Documentación Diseño | B30: 4.21 EEM17 Room Heating Controls with Thermostatic Valves | C30: =SUM(H30:K30) -> 6 | D30: 0.2 | E30: =_xlfn.WORKDAY.INTL(F29, 1, 1,'PONER VACACIONES'!$B$4:$B$24) -> #REF! | F30: =_xlfn.WORKDAY.INTL(E30, D30*5, 1,'PONER VACACIONES'!$B$4:$B$24) -> #REF! | G30: Revisar planos y especificaciones de controles de calefacción para confirmar instalación de válvulas termostáticas. Validar fichas técnicas y elaborar cuadro resumen de espacios servidos. Llenar EDGE App y subir documentación correspondiente. | H30: 3 | I30: 2 | J30: 1 | K30: 0 | L30: =H30 -> 3 | M30: =I30 -> 2 | N30: =J30 -> 1 | O30: =K30 -> 0 | P30: FALSE
A31: 4. EDGE Expert: Documentación Diseño | B31: 4.22 EEM18 Domestic Hot Water (DHW) System | C31: =SUM(H31:K31) -> 2.5 | D31: 0.2 | E31: =_xlfn.WORKDAY.INTL(F26, 1, 1,'PONER VACACIONES'!$B$4:$B$24) -> #REF! | F31: =_xlfn.WORKDAY.INTL(E31, D31*5, 1,'PONER VACACIONES'!$B$4:$B$24) -> #REF! | G31: Revisar planos de sistema de agua caliente, revisar eficiencia en fichas técnicas, llenar la calculadora en la EDGE App y subir la documentación correpondiente. | H31: 2 | I31: 0.5 | J31: 0 | K31: 0 | L31: =H31 -> 2 | M31: =I31 -> 0.5 | N31: =J31 -> 0 | O31: =K31 -> 0 | P31: FALSE
A32: 4. EDGE Expert: Documentación Diseño | B32: 4.23 EEM19 Domestic Hot Water Preheating System | C32: =SUM(H32:K32) -> 6 | D32: 0.2 | E32: =_xlfn.WORKDAY.INTL(F31, 1, 1,'PONER VACACIONES'!$B$4:$B$24) -> #REF! | F32: =_xlfn.WORKDAY.INTL(E32, D32*5, 1,'PONER VACACIONES'!$B$4:$B$24) -> #REF! | G32: Revisar planos y memoria de sistemas de agua caliente para identificar equipos de pre-calentamiento. Validar fichas técnicas y elaborar cuadro resumen de capacidad instalada. Llenar EDGE App y subir documentación correspondiente. | H32: 3 | I32: 2 | J32: 1 | K32: 0 | L32: =H32 -> 3 | M32: =I32 -> 2 | N32: =J32 -> 1 | O32: =K32 -> 0 | P32: FALSE
A33: 4. EDGE Expert: Documentación Diseño | B33: 4.24 EEM20 Economizers | C33: =SUM(H33:K33) -> 5 | D33: 0.2 | E33: =_xlfn.WORKDAY.INTL(F32, 1, 1,'PONER VACACIONES'!$B$4:$B$24) -> #REF! | F33: =_xlfn.WORKDAY.INTL(E33, D33*5, 1,'PONER VACACIONES'!$B$4:$B$24) -> #REF! | G33: Revisar planos y fichas técnicas de unidades HVAC para confirmar incorporación de economizadores de aire exterior. Elaborar cuadro de equipos con economizador y documentar en EDGE App con soporte gráfico. | H33: 2.5 | I33: 2 | J33: 0.5 | K33: 0 | L33: =H33 -> 2.5 | M33: =I33 -> 2 | N33: =J33 -> 0.5 | O33: =K33 -> 0 | P33: FALSE
A34: 4. EDGE Expert: Documentación Diseño | B34: 4.25 EEM21 Demand Control Ventilation Using CO2 Sensors | C34: =SUM(H34:K34) -> 6 | D34: 0.2 | E34: =_xlfn.WORKDAY.INTL(F33, 1, 1,'PONER VACACIONES'!$B$4:$B$24) -> #REF! | F34: =_xlfn.WORKDAY.INTL(E34, D34*5, 1,'PONER VACACIONES'!$B$4:$B$24) -> #REF! | G34: Revisar planos y memoria de ventilación para confirmar ubicación de sensores de CO₂ y su integración con el sistema. Validar fichas técnicas y elaborar cuadro resumen de unidades controladas. Llenar EDGE App y subir documentación correspondiente. | H34: 3 | I34: 2 | J34: 1 | K34: 0 | L34: =H34 -> 3 | M34: =I34 -> 2 | N34: =J34 -> 1 | O34: =K34 -> 0 | P34: FALSE
A35: 4. EDGE Expert: Documentación Diseño | B35: 4.26 EEM22 Efficient Lighting for Internal Areas | C35: =SUM(H35:K35) -> 3 | D35: 0.2 | E35: =_xlfn.WORKDAY.INTL(F26, 1, 1,'PONER VACACIONES'!$B$4:$B$24) -> #REF! | F35: =_xlfn.WORKDAY.INTL(E35, D35*5, 1,'PONER VACACIONES'!$B$4:$B$24) -> #REF! | G35: Revisar planos de iluminación interior, revisar lumenes por watts de consumo en fichas técnicas, generar una calculadora para determinar eficacia luminosa, llenar apartado en la EDGE App y subir la documentación correpondiente. | H35: 2 | I35: 0.5 | J35: 0.5 | K35: 0 | L35: =H35 -> 2 | M35: =I35 -> 0.5 | N35: =J35 -> 0.5 | O35: =K35 -> 0 | P35: FALSE
A36: 4. EDGE Expert: Documentación Diseño | B36: 4.27 EEM23 Efficient Lighting for External Areas | C36: =SUM(H36:K36) -> 2 | D36: 0.2 | E36: =_xlfn.WORKDAY.INTL(F26, 1, 1,'PONER VACACIONES'!$B$4:$B$24) -> #REF! | F36: =_xlfn.WORKDAY.INTL(E36, D36*5, 1,'PONER VACACIONES'!$B$4:$B$24) -> #REF! | G36: Revisar planos de iluminación exterior, revisar lumenes por watts de consumo en fichas técnicas, generar una calculadora para determinar eficacia luminosa, llenar apartado en la EDGE App y subir la documentación correpondiente. | H36: 1.5 | I36: 0.5 | J36: 0 | K36: 0 | L36: =H36 -> 1.5 | M36: =I36 -> 0.5 | N36: =J36 -> 0 | O36: =K36 -> 0 | P36: FALSE
A37: 4. EDGE Expert: Documentación Diseño | B37: 4.28 EEM24 Lighting Controls | C37: =SUM(H37:K37) -> 3.5 | D37: 0.2 | E37: =_xlfn.WORKDAY.INTL(F36, 1, 1,'PONER VACACIONES'!$B$4:$B$24) -> #REF! | F37: =_xlfn.WORKDAY.INTL(E37, D37*5, 1,'PONER VACACIONES'!$B$4:$B$24) -> #REF! | G37: Revisar planos de iluminación, revisar cumplimiento de los sensores de iluminación, investigar fichas técnicas, llenar apartado en la EDGE App y subir la documentación correpondiente. | H37: 2 | I37: 1 | J37: 0.5 | K37: 0 | L37: =H37 -> 2 | M37: =I37 -> 1 | N37: =J37 -> 0.5 | O37: =K37 -> 0 | P37: FALSE
A38: 4. EDGE Expert: Documentación Diseño | B38: 4.29 EEM25 Skylights | C38: =SUM(H38:K38) -> 5 | D38: 0.2 | E38: =_xlfn.WORKDAY.INTL(F37, 1, 1,'PONER VACACIONES'!$B$4:$B$24) -> #REF! | F38: =_xlfn.WORKDAY.INTL(E38, D38*5, 1,'PONER VACACIONES'!$B$4:$B$24) -> #REF! | G38: Revisar planos y dimensiones de los skylights para sacar áreas de iluminación natural, revisar fichas técnicas de los cristales, incorporar planos de iluminación con los sensores de luz diurna, llenar apartado en EDGE APP y subir documentación correspondiente. | H38: 3 | I38: 1.5 | J38: 0.5 | K38: 0 | L38: =H38 -> 3 | M38: =I38 -> 1.5 | N38: =J38 -> 0.5 | O38: =K38 -> 0 | P38: FALSE
A39: 4. EDGE Expert: Documentación Diseño | B39: 4.30 EEM26 Demand Control Ventilation for Parking Using CO2 Sensors | C39: =SUM(H39:K39) -> 6 | D39: 0.2 | E39: =_xlfn.WORKDAY.INTL(F38, 1, 1,'PONER VACACIONES'!$B$4:$B$24) -> #REF! | F39: =_xlfn.WORKDAY.INTL(E39, D39*5, 1,'PONER VACACIONES'!$B$4:$B$24) -> #REF! | G39: Revisar planos de ventilación de estacionamientos para confirmar ubicación de sensores de CO₂. Validar fichas técnicas, elaborar cuadro resumen de equipos controlados, llenar EDGE App y subir documentación correspondiente. | H39: 3 | I39: 2 | J39: 1 | K39: 0 | L39: =H39 -> 3 | M39: =I39 -> 2 | N39: =J39 -> 1 | O39: =K39 -> 0 | P39: FALSE
A40: 4. EDGE Expert: Documentación Diseño | B40: 4.31 EEM27* Insulation for Cold Storage Envelope | C40: =SUM(H40:K40) -> 6 | D40: 0.2 | E40: =_xlfn.WORKDAY.INTL(F39, 1, 1,'PONER VACACIONES'!$B$4:$B$24) -> #REF! | F40: =_xlfn.WORKDAY.INTL(E40, D40*5, 1,'PONER VACACIONES'!$B$4:$B$24) -> #REF! | G40: Revisar planos arquitectónicos de cámaras de refrigeración, validar espesores y materiales de aislamiento en fichas técnicas. Elaborar cuadro resumen de conductividades y registrar en EDGE App con documentación de soporte. | H40: 3 | I40: 2 | J40: 1 | K40: 0 | L40: =H40 -> 3 | M40: =I40 -> 2 | N40: =J40 -> 1 | O40: =K40 -> 0 | P40: TRUE
...

Sheet Hoja 1
A1: Bloque | B1: Actividad | C1: Duracion (semanas) | D1: Fecha inicio | E1: Fecha fin | F1: Descripción de actividades | G1: CJ | H1: CS | I1: PM | J1: Auditor | K1: HPen CJ | L1: HPen CS | M1: HPen PM | N1: HPen Auditor | O1: Críticas
A2: 0. Carga en Smart Suite | B2: 0.1 Gestión de proyecto | C2: 0.2 | D2: 45840 | E2: 45841 | F2: Gestionar y programar el WBS del proyecto en Smart Suite. | G2: 0 | H2: 0 | I2: 6 | J2: 0 | K2: 0 | L2: 0 | M2: 6 | N2: 0 | O2: FALSE
A3: 1. Seguimiento | B3: 1.1 Reuniones con el cliente | C3: 120 | D3: 45840 | E3: 46696 | F3: Atender reuniones con el cliente | G3: 0 | H3: 4 | I3: 8 | J3: 0 | K3: 0 | L3: 4 | M3: 8 | N3: 0 | O3: FALSE
A4: 1. Seguimiento | B4: 1.2 Kick-off | C4: 0.2 | D4: 45841 | E4: 45842 | F4: Exponer ante el cliente el comportamiento del proyecto en EDGE. Explicar las estrategias a seguir y las metas de la certificación. | G4: 0 | H4: 1 | I4: 1 | J4: 0 | K4: 0 | L4: 1 | M4: 1 | N4: 0 | O4: FALSE
A5: 2. EDGE Expert: Diseño Integrado | B5: 2.1 Evaluación inicial en EDGE App | C5: 0.2 | D5: 45845 | E5: 45846 | F5: Revisar la información compartida y evaluar el proyecto en la EDGE App. | G5: 2 | H5: 3 | I5: 1 | J5: 0 | K5: 2 | L5: 3 | M5: 1 | N5: 0 | O5: FALSE
A6: 2. EDGE Expert: Diseño Integrado | B6: 2.2 Revisión de diseño arquitectónico y de ingeniería | C6: 1 | D6: 45845 | E6: 45852 | F6: Revisar los avances de las ingenierías del proyecto detéctando áreas de oportunidad y mejora para cumplir con los objetivos de EDGE. | G6: 2 | H6: 5 | I6: 1 | J6: 0 | K6: 2 | L6: 5 | M6: 1 | N6: 0 | O6: FALSE
A7: 3. EDGE Expert: Seguimiento | B7: 3.1. Reuniones de seguimiento con cliente | C7: 12 | D7: 45845 | E7: 45930 | F7: Programar y llevar reuniones con el cliente y los equipos de trabajo para explicar si se está cumpliendo con las estrategias persegidas. | G7: 0 | H7: 6 | I7: 12 | J7: 0 | K7: 0 | L7: 6 | M7: 12 | N7: 0 | O7: FALSE
A8: 3. EDGE Expert: Seguimiento | B8: 3.2 Coordinación con equipo de diseño y ajustes | C8: 4 | D8: 45842 | E8: 45870 | F8: Capacitaciones para el equipo de diseño, revisión de planos y sugerencias. | G8: 0 | H8: 4 | I8: 8 | J8: 0 | K8: 0 | L8: 4 | M8: 8 | N8: 0 | O8: FALSE
A9: 4. EDGE Expert: Documentación Diseño | B9: 4.1 Alta del proyecto en EDGE APP y verificación de versión | C9: 0.2 | D9: 45873 | E9: 45874 | F9: Realizar el registro del proyecto, solicitar al cliente los datos de registro a través de un RFI. | G9: 0 | H9: 2 | I9: 1 | J9: 0 | K9: 0 | L9: 2 | M9: 1 | N9: 0 | O9: FALSE
A10: 4. EDGE Expert: Documentación Diseño | B10: 4.2 Configuración de parámetros base y tipologías | C10: 0.2 | D10: 45846 | E10: 45847 | F10: Definir y generar tipologías del proyecto | G10: 2 | H10: 1 | I10: 0 | J10: 0 | K10: 2 | L10: 1 | M10: 0 | N10: 0 | O10: FALSE
A11: 4. EDGE Expert: Documentación Diseño | B11: 4.3. Revisión de planos y fichas técnicas | C11: 120 | D11: 45846 | E11: 46702 | F11: Revisión de planos as-built y fichas técnicas, generación de issues log y recomendaciones. | G11: 2 | H11: 3 | I11: 1 | J11: 0 | K11: 2 | L11: 3 | M11: 1 | N11: 0 | O11: FALSE
A12: 4. EDGE Expert: Documentación Diseño | B12: 4.4 Design | C12: 0.2 | D12: 45845 | E12: 45846 | F12: Realizar el llenado de la pestaña de diseño en EDGE App. Subir los documentos correspondientes. | G12: 2.5 | H12: 1.5 | I12: 0.5 | J12: 0 | K12: 2.5 | L12: 1.5 | M12: 0.5 | N12: 0 | O12: FALSE
A13: 4. EDGE Expert: Documentación Diseño | B13: 4.5 EEM01* Window-to-Wall Ratio | C13: 0.2 | D13: 45845 | E13: 45846 | F13: Revisar los alzados del proyecto para calcular la proporción de ventana-muro, llenar calculadora en EDGE App y subir documentación correspondiente. | G13: 2.5 | H13: 2 | I13: 0.5 | J13: 0 | K13: 2.5 | L13: 2 | M13: 0.5 | N13: 0 | O13: TRUE
... A93: 10. Cierre de proyecto | B93: 10.1 Entrega de resumen y cierre | C93: 0.2 | D93: 46724 | E93: 46727 | F93: Compartir al cliente el certificado de su proyecto, adjuntar un press realease y un book de cierre del proyecto. Apoyar en la solicitud de la placa EDGE. | G93: 0 | H93: 1.5 | I93: 1.5 | J93: 0 | K93: 0 | L93: 1.5 | M93: 1.5 | N93: 0 | O93: FALSE

Sheet Hoja 2
B3: ID Etapa | C3: Orden | D3: Etapa | E3: Abreviatura
B4: =C4&". "&D4 -> 0. Carga en Smart Suite | C4: 0 | D4: Carga en Smart Suite | E4: CSS
B5: =C5&". "&D5 -> 1. Seguimiento | C5: 1 | D5: Seguimiento | E5: SEGI
B6: =C6&". "&D6 -> 2. EDGE Expert: Diseño Integrado | C6: 2 | D6: EDGE Expert: Diseño Integrado | E6: EEDis
B7: =C7&". "&D7 -> 3. EDGE Expert: Seguimiento | C7: 3 | D7: EDGE Expert: Seguimiento | E7: EESeg
B8: =C8&". "&D8 -> 4. EDGE Expert: Documentación Diseño | C8: 4 | D8: EDGE Expert: Documentación Diseño | E8: EEDDis
B9: =C9&". "&D9 -> 5. EDGE Auditor Diseño | C9: 5 | D9: EDGE Auditor Diseño | E9: EEAudD
B10: =C10&". "&D10 -> 6. EDGE Expert: Correcciones Diseño | C10: 6 | D10: EDGE Expert: Correcciones Diseño | E10: EECorrD
B11: =C11&". "&D11 -> 7. EDGE Expert: Documentación Construcción | C11: 7 | D11: EDGE Expert: Documentación Construcción | E11: EEDCon
B12: =C12&". "&D12 -> 8. EDGE Auditor Construcción | C12: 8 | D12: EDGE Auditor Construcción | E12: EAuditC
B13: =C13&". "&D13 -> 9. EDGE Expert: Correcciones Construcción | C13: 9 | D13: EDGE Expert: Correcciones Construcción | E13: EECorrC
B14: =C14&". "&D14 -> 10. Cierre de proyecto | C14: 10 | D14: Cierre de proyecto | E14: CP
